Workbook
Name Academia: #REF!
Name Academia_Consultant: #REF!
Name Academia_Project_Management: #REF!
Name Academia_Science_and_Research: #REF!
Name Academia_Support: #REF!
Name AcademiaAdministrativeSupportCategories: Constants!$A$57:$A$58
Name AcademiaConsultantCategories: Constants!$A$54
Name AcademiaLaborGroups: [1]Constants!$A$18:$A$21
Name AcademiaLaborGroups: [1]Constants!$A$18:$A$21
Name AcademiaLaborGroups: [2]Constants!$A$21:$A$24
Name AcademiaLaborGroups: [1]Constants!$A$18:$A$21
Name AcademiaLaborGroups: [3]Constants!$A$21:$A$24
Name AcademiaLaborGroups: [1]Constants!$A$18:$A$21
Name AcademiaLaborGroups: [4]Constants!$A$21:$A$24
Name AcademiaLaborGroups: Constants!$A$21:$A$24
Name AcademiaProjectManagementCategories: Constants!$A$34:$A$37
Name AcademiaResearchCategories: Constants!$A$40:$A$51
Name ff.dlrs.Base: 'Total Amount'!#REF!
Name ff.dlrs.Op1: 'Total Amount'!#REF!
Name ff.dlrs.Op2: 'Total Amount'!#REF!
Name ff.dlrs.Op3: 'Total Amount'!#REF!
Name ff.dlrs.Op4: 'Total Amount'!#REF!
Name ff.dlrs.Op5: 'Total Amount'!#REF!
Name General: #REF!
Name General_Consultant: #REF!
Name General_Science_and_Research: #REF!
Name General_Software_Development: #REF!
Name General_Support: #REF!
Name GeneralConsultantCategories: Constants!$A$96
Name GeneralLaborGroups: [1]Constants!$A$24:$A$29
Name GeneralLaborGroups: [1]Constants!$A$24:$A$29
Name GeneralLaborGroups: [2]Constants!$A$27:$A$32
Name GeneralLaborGroups: [1]Constants!$A$24:$A$29
Name GeneralLaborGroups: [3]Constants!$A$27:$A$32
Name GeneralLaborGroups: [1]Constants!$A$24:$A$29
Name GeneralLaborGroups: [4]Constants!$A$27:$A$32
Name GeneralLaborGroups: Constants!$A$27:$A$31
Name GeneralManufacturingCategories: Constants!$A$85:$A$92
Name GeneralProjectManagementCategories: Constants!$A$67:$A$70
Name GeneralScienceandEngineeringCategories: Constants!$A$73:$A$76
Name GeneralSoftwareDevelopmentCategories: Constants!$A$79:$A$82
Name GeneralSupportCategories: Constants!$A$61:$A$64
Name Indirect.Rate.Table: #REF!
Name IndirectRateCategories: [1]Constants!$A$109:$A$124
Name IndirectRateCategories: [1]Constants!$A$109:$A$124
Name IndirectRateCategories: [2]Constants!$A$113:$A$129
Name IndirectRateCategories: [1]Constants!$A$109:$A$124
Name IndirectRateCategories: [3]Constants!$A$121:$A$138
Name IndirectRateCategories: [1]Constants!$A$109:$A$124
Name IndirectRateCategories: [4]Constants!$A$113:$A$128
Name IndirectRateCategories: Constants!$A$102:$A$118
Name Labor.Rates.Table: 'Labor Rates'!$B$7:$AN$32
Name Labor_Cats_Sorted_Table: Constants!$A$100:$A$146
Name LaborCollection: [1]Constants!$A$12
Name LaborCollection: [1]Constants!$A$12
Name LaborCollection: [2]Constants!$A$15
Name LaborCollection: [1]Constants!$A$12
Name LaborCollection: [3]Constants!$A$15
Name LaborCollection: [1]Constants!$A$12
Name LaborCollection: [4]Constants!$A$15

Sheet Change Notes
A1: Version ID | B1: Tab | C1: Changes from Previous
A2: 12-2019 | C2: Original Version used for BTO BAA.
A3: 01-2020.1 | B3: Base, all Options, Tasks | C3: In Base and all Option tabs and two TASK tabs, column Q in Labor Rates table, now refers to correct column (N) instead of (M). Incorrect column caused Fringe Benefit Rate to be used instead of Labor Overhead Rate in calculations. This was only incorrect for the second fiscal year (only column Q).
A4: 01-2020.1 | B4: Base, all Options, Tasks | C4: In all of the same tabs described above, cell U72 was distributed with "10%" as the default value. This is changed to be 0%
A5: 01-2020.1 | B5: Summary Cost Table | C5: Removed the inclusion of row D (hours) in the Checksum value in the bottom row.
A6: 03-2020 | B6: Base, all Options, Tasks | C6: Summed the Hours for Consultants.
A7: 03-2020 | B7: General | C7: Updated the General Instructions Word document.
A8: 03-2020 | B8: Base | C8: Yellow highlights added to column B.
A9: 04-2020 | B9: Constants | C9: There were two "Program/Project Manager III" categories. Changed second one to be "Program/Project Manager II"
A10: 1.04.00 | B10: General | C10: Top, added CAGE codes and proposer's proposal ID.
A11: 1.04.00 | B11: Constants | C11: Added Fringe, Overhead (Labor), G&A (Labor) and F&A (Labor) to the Indirect Rates list.
A12: 1.04.00 | B12: General | C12: Cells B18 & B19 instructions expanded.
A13: 1.04.00 | B13: Labor Rates | C13: Updated A7, B7 to include the word "Required".
A14: 1.04.00 | B14: Offeror Constants | C14: Replaced out-year fiscal year dates with formulas that add 12 months to the prior FY date. Plus conditional formatting on FY Begin Dates.
... A27: 1.06.02 | B27: Indirect Rates and Profit_Fee | C27: Increased precision of percentages to seven decimal places, primarily for Cost of Money

Sheet Constants
A1: Spreadsheet Version Number
A2: 1.06.02 | B2: First digit change --> prior functions changes. Second digit change --> new function added. Third digit change --> change in spreadsheet that does not affect CPDB.
A4: SpecificAnnouncementNumber
A7: General, I2, Picklist of Offeror Business Types | D7: Cell Range Naming Conventions:
A8: Large Business | D8: ThisIsAName = internal constants such as pick-lists
A9: Small Business | D9: This.Is.a.Name = named ranges holding proposer data
A10: Non-Profit
A11: Academia
A12: Lab/FFRDC | D12: Labor Collection --> Labor Group --> Labor Category
A14: Labor Collection based on Offeror Business Type Selection | C14: =CONCATENATE("Offeror.Bus.Type is ",Offeror.Bus.Type) -> Offeror.Bus.Type is Large Business
A15: =IF(Offeror.Bus.Type = "", "",IF(Offeror.Bus.Type = "Academia","Academia","General")) -> General | B15: Valid values are Academia or General | D15: Add/Change Labor Collection requires Data Validation code change on Labor Rates tab, and new Labor Group list below.
A17: No Business Type Selected | B17: instructional choice
A18: First select a Business Type | B18: No Labor Collection is available
A20: Academia Labor Groups | D20: Add/Change Labor Group requires changes below to Categories
A21: Project Management
A22: Research
A23: Consultant
A24: Administrative Support
A26: General Labor Groups
A27: Project Management
A28: Science and Engineering
A29: Software Development
A30: Consultant
A31: Support
A33: Academia Project Management Categories
A34: Principal Investigator
... A168: Business

Sheet Instructions
B2: ARPA-H WORKBOOK INSTRUCTIONS
B4: • These instructions describe how to use this ARPA-H Standard Cost Proposal Workbook when an Other Transaction using a Resource Sharing agreement is contemplated. Proposers shall use a different Workbook for proposals that do not contemplate Resource Sharing. These instructions do not replace or supersede the cost proposal instructions given in the solicitation or announcement.
B5: • This Workbook is to be used by both a Prime Proposer and its Subproposers. While each Proposer and Subproposer must complete the Workbook for its own organziation, the Prime may submit all Workbooks. Subproposers may submit theirs separately if they so choose.
B6: • The instructions that follow apply to the tabs that are colored; the spreadsheets within these tabs are linked together using references and formulas. The non-colored/white tabs, such as Subproposer, Travel, etc. contain stand-alone spreadsheets that provide for expression of cost proposal details as required. Formulas, etc. may be modified within the standalone tab spreadsheets (i.e., subproposer, consultants, travel, materials-supplies, equipment, ODC details, and expenditures by month). You may add tabs and spreadhseets to the Workbook to clarify a proposal.
B7: • Note that, in addition to the instructions provided herein, each spreadsheet may have additional guidance and instructions on it.
B9: Spreadsheets
B10: All Speadsheets | C10: • DO NOT DELETE tabs, spreadsheets, or rows or columns within spreadsheets in this template. This will damage the structure of the Workbook. If you don't want to see a tab, row, or column, use the Hide function.
C11: • Before entering detailed proposal data, Proposers must begin with the "General" tab, where the Proposing- and the Prime organization name(s) (and other data) will be entered. Proposers then complete the "Proposer Constants" tab where a Business Type will be selected. When those are done, the unshaded cells within the tabs entitled" Labor Rates", "Phase # Costs," and "Ph # Task $ "must be filled in, followed by completion of the remaining spreadsheets (the uncolored tabs) that are included in the Workbook, as applicable.
C12: • Except for the "Total Amount" Spreadsheet and all Instructions throughout the workbook, unshaded/clear cells are for data entry. Colored/shaded cells indicate references or formulas that should not be changed unless the reference or formula does not match the proposing organization's business rules. If these references/formulas are changed, you must ensure the change does not affect the overall flow of the spreadsheet or workbook. There are notes throughout the Workbook to assist in data input. The "Total Amount" Spreadsheet pulls in data from all of the other spreadsheets and does not require any data input whatsoever.
C13: • When asked to select from a pick-list, choose the closest option presented.
C14: • If the Proposer needs to add a new line within any spreadsheet, that line must be added to the remaining associated speadsheets and done carefully, ensuring all appropriate formulas carry forward, and are duplicated in all like-spreadsheets. It is often easier to simply add the additional data to another complete Workbook and refer to such in the Cost Proposal write-up.
B16: General Tab Spreadsheet | C16: • Complete cells D4, D5, D6, D7, E4, and E5. (The CAGE codes and an accurate ARPA-H solicitation number are helpful.)
C17: • The "Summary of Proposed Total Costs" section of the General tab spreadsheet will self-complete as cost data is entered into the "Phase # Costs" spreadsheet(s).
B19: Proposer Constants Tab Spreadsheet | C19: • Click on cell B5 of the "Proposer Constants" spreadsheet; a small arrow in the bottom right hand corner of that cell will appear. Click on that arrow and a drop-down list of several organization types will appear. Select the organization type that best describes the Proposer. (If this selection is changed, the "ARPA-H Labor Group" and "ARPA-H Labor Category" will have to be reselected for each person the "Labor Rates" spreadsheet.) If "Small Business" is selected, cells D5 and E5 will activate. Clicking on cell E5 causes a small arrow in the bottom right hand corner of that cell to appear. Click on that arrow, and a drop-down list of numbers appears that is used to identify the number of employees in the Proposing Organization; select the appropriate number.
C20: • Proposer Accounting Periods describe the begin/end dates for your organization's accounting periods. Complete cells C14 and C15 through H14 and H15. Do not leave a gap between accounting periods.
C21: • Change the Labels in Cells C13-H13 as the Proposer sees fit. These labels will appear on line 6 above the Direct Labor costs FY in each of the "Phase # Costs" spreadsheets.
C22: • This Workbook provides Proposers with up to six fiscal years for each phase of their proposal, which is typically more than sufficient for ARPA-H R&D efforts. Proposers should not use all six fiscal years or all Phase Cost spreadsheets if they are not applicable. If Proposers need more fiscal years (or accounting periods), use a second Workbook -- do not attempt to add fiscal years to this Workbook's spreadsheets.
B24: Labor Rates Tab Spreadsheet | C24: • This Workbook relies heavily on the data within the "Labor Rates" spreadsheet. This is where labor categories and labor rates that feed through to the cost details of the rest of the Workbook are listed.
C25: • Each person assigned to the R&D effort is represented under colums B-E, rows 8-31 of this spreadsheet. (The data within columns F, H, J, L, N, and P will pull through to the spreadsheets within the "Phase # Costs" spreadsheets.) Within each cell (rows 8-31) of Column E, put the full name of each person assigned to this project. In column D, type in the Proposer's labor category for each person identified un Column E. Then, under Column B, click on cell B8 and a small arrow will appear in the bottom right corner. Click on that arrow and select from the list of ARPA-H labor groups that closest match that person's labor category/job title. Do this for each cell within column B through cell B31 for each person in Column E. Repeat the same process for Column C for the ARPA-H labor categories. (The descriptions of ARPA-H labor categories are in Cells C39-C48.)
C26: • Next, complete Cells F8-F31 (as applicable) and provide the fully loaded (all labor overheads added) base labor rate for each person, and then only the escalation rates threafter in columns G, I, K, M, and O. The spreadsheet will do all of the calculations; all of the fully loaded rates will pull through to the "Phase # Costs" spreadsheets. The only labor-related data that will need to be entered into the "Phase # Costs" spreadsheets are the number of hours for each person for each of the fiscal years that apply in each Phase.
C27: • When the Proposer's organization doesn't normally operate on an hourly rate basis (e.g., annual salary data), insert a formula in each Cell from F8 to F31 that divides the appropriate basis by the appropriate number of Full Time Equivalent (FTE) labor hours (for example: = [annual salary]/1,920, or 1,840); etc. (1,920 allows for 10 federal holidays and 80 hours of leave; 1,840 allows for the holidays and 4 weeks of leave).) This formula will derive the hourly rate needed. It only needs to be done once, in the base year's labor rate fields.
C28: • If more lines for personnel are needed than the 24 provided, see the instructions below to add more lines to the "Labor Rates"sheet and the "Phase # Costs" sheets.
B30: Phase # Cost Tabs Spreadsheets | C30: • Do not change the labor categories or names of personnel on the "Phase # Costs" spreadsheets. All of those changes must be done on the "Labor Rates" spreadsheet.
C31: • The labor categories and personnel names that appear in columns A, B, and C of each "Phase # Costs" spreadsheet come from columns D and E of the "Labor Rates" spreadsheet. All "Phase # Costs" spreadsheets should have the same personnel listed in Rows 8-31. For example, if you have a particular person who will only be involved during Phase 2, that person's name should be listed on all "Phase # Costs" spreadsheets, but will have hours and associated costs showing only within the "Phase 2 Costs" spreadsheet.
C32: • Proposers may add additional specific cost categories (Subproposer, ODC types, etc.) as needed but must ensure those new cost categories track to the "Total Amount" spreadsheet. Add more rows as necessary, but ensure that all formulas carry forward.
B34: ADDING ROWS
B35: • This spreadsheet is designed to handle the addition of rows only; not the addition or removal of columns. Use the Hide function to hide rows or columns that are not needed.
B36: • When adding rows to a spreadsheet, it must be done consistently for all related sheets. In the event more than the 24 rows provided for labor categories is needed, it is best to simply add those personnel and their associated data and costs to a new Workbook. If, however, you want to add people to the "Phase # Costs" sheets, you must begin with the "Labor Rates" sheet, where you will click on any of the rows between 8 and 31, insert the number of lines needed, copy the formulas from the row above the added line(s), paste them into the new row(s), and add the requested data. You must do the same for each of the "Phase # Costs" sheets and the "Total Amount" spreadsheet. If done correctly, all of the data within the "Labor Rates" sheet will be automatically pulled in to the "Phase # Costs" sheets, which will then transfer to the "Total Amount" sheet.

Sheet General
B2: GENERAL INFORMATION
B4: Proposer Name: | D4: Name | G4: Proposer's CAGE Code
B5: Prime Proposer: | D5: Name | G5: Prime's CAGE Code
B6: Solicitation No. | D6: Number
B7: Proposer's Proposal ID: | D7: ID
C9: GENERAL INFORMATION
C10: The information acquired by this Workbook will assist government personnel in performing their review and evaluation of the cost proposals submitted by Proposers, and will assist with negotiations should they take place. Providing adequate supporting data and attachments, and establishing reasonableness of proposed costs, is solely the responsibility of Proposers; therefore, it is in each Proposer’s best interest to submit a fully supportable and well-prepared cost proposal, to include the basis of and rationale for all proposed costs, so the information provided can be relied upon as being current, complete, and accurate.
C12: In addition to providing detailed cost summaries by Phase, each Proposer must provide a breakdown of costs by the Tasks identified in the statement of work. The "Ph # Task $" tabs provide the spreadsheets (sheets) needed to capture this data. The sum of all costs for each Task sheet (Cells M59 and N58 of each Ph # Task $" sheet) must equal the total cost summary identified in yellow (Cell O61), which is being pulled from Cell AD79 of that Phase's "Phase # Costs" sheet.
C13: Any Phase that is not priced will not be included in any resulting award.
C14: • Enter the proposed cost detail in the "Phase # Costs" sheets for each Phase that applies to your proposal. The tab entitled "Total Amount" will automatically calculate from the figures entered into the "Phase" sheets.
C16: • Before entering data in any "Phase # Costs" sheet, the non-highlighted/white fields on the "General", "Proposer Constants", and "Labor Rates" sheets must be completed. A business type on the "Proposer Constants" sheet must be selected before "Labor Groups" and "Labor Categories" can be selected in "Labor Rates" sheet.
C17: • Proposers may add additional specific cost categories (Subproposers, ODC types, etc.) as needed but must ensure those new cost categories track to the "Total Amount" sheet. See the Instructions tab for details.
C18: • Unshaded/White cells are for data entry. Highlighted cells indicate references or formulas that should not be changed unless the formula does not match the Proposer's business rules. If these formulas are changed, the Proposer must ensure the change does not affect the overall flow of the Workbook.
C19: • Ensure all costs from other sheets are correct.
C20: • If a row, column, or sheet in this Workbook is not needed for your proposal, either ignore it or hide it; do not delete it.
C22: Summary of Proposed Total Costs. This chart will automatically fill in from the "Total Amount" sheet. | J22: ARPA-H is interested in your feedback. If you have suggestions for improving this Workbook, please send an e-mail to elizabeth.fuller@arpa-h.gov
D23: ='Total Amount'!B32 -> Total Direct Labor | E23: ='Total Amount'!X32 -> 0
D24: ='Total Amount'!B39 -> Total Subproposers | E24: ='Total Amount'!W39 -> 0
D25: ='Total Amount'!B47 -> Total Consultants | E25: ='Total Amount'!X47 -> 0
D26: ='Total Amount'!B54 -> Total Other Direct Costs | E26: ='Total Amount'!W54 -> 0
D27: ='Total Amount'!B59 -> Total Material Handling | E27: ='Total Amount'!W59 -> 0
D28: ='Total Amount'!B61 -> SUBTOTAL PRIOR TO INDIRECTS AND PROFIT | E28: ='Total Amount'!W62 -> 0
D29: ='Total Amount'!B67 -> Total G&A | E29: ='Total Amount'!W67 -> 0
D30: ='Total Amount'!B69 -> SUBTOTAL PRIOR TO FCCM | E30: ='Total Amount'!W70 -> 0
D31: ='Total Amount'!B75 -> Total FCCM | E31: ='Total Amount'!W75 -> 0
D32: ='Total Amount'!B77 -> Total Estimated Costs | E32: ='Total Amount'!X78 -> 0
D34: Government Share | E34: ='Total Amount'!X81 -> 0
D35: Performer Share | E35: ='Total Amount'!X82 -> 0

Sheet Proposer Constants
B2: PROPOSER DATA THAT AFFECTS THE WORKBOOK
B4: Proposer's Business Type: | D4: Small Business Size Estimate:
B5: Large Business | C5: Cell B4 is a drop-down-list. Click on cell B4 and the arrow at the bottom right end of the cell will activate. Choose from the drop-down list that appears. If "Small Business" is chosen, cells D4 and E4 will activate. | D5: 1000+ | E5: This is a drop-down list. Click on Cell D4 and the arrow at the bottom right end of the cell will activate. Choose from the drop-down list that appears.
B11: Proposer Accounting Periods
B12: Enter the expected date range of each accounting period from the Proposer's perspective. A period represents a change in hourly- or indirect cost rates.
B13: Proposer's Preferred Label (modify): | C13: FY 1 | D13: FY 2 | E13: FY 3 | F13: FY 4 | G13: FY 5 | H13: FY 6
B14: Fiscal Year Begins Date: | C14: 45809 | D14: =EDATE(C14,12) -> 46174 | E14: =EDATE(D14,12) -> 46539 | F14: =EDATE(E14,12) -> 46905 | G14: =EDATE(F14,12) -> 47270 | H14: =EDATE(G14,12) -> 47635
B15: Fiscal Year Ends Date: | C15: 46173 | D15: =EDATE(C15,12) -> 46538 | E15: 46904 | F15: =EDATE(E15,12) -> 47269 | G15: =EDATE(F15,12) -> 47634 | H15: =EDATE(G15,12) -> 47999
B17: Note 1 - A "Fiscal Year Begins Date" should be one day after the "Fiscal Year Ends Date" of the prior fiscal year (or accounting period). Cells will turn red if this condition is not met.
B18: Note 2 - Proposers should put the period of performance for each Phase in cell C2 of each "Phase # Costs" sheet.

Sheet Summary Cost Table
B1: Proposer Fiscal Year Labels: | C1: =Period1_Label -> FY 1 | D1: =Period2_Label -> FY 2 | E1: =Period3_Label -> FY 3 | F1: =Period4_Label -> FY 4 | G1: =Period5_Label -> FY 5 | H1: =Period6_Label -> FY 6
B2: Hours Proposed in Each Fiscal Year: | C2: ='Phase 1 Costs'!E33+'Phase 2 Costs '!D32+'Phase 3 Costs'!D32+'Phase 4 Costs'!D32+'Phase 5 Costs'!D32+'Phase 6 Costs'!D32 -> 0 | D2: ='Phase 1 Costs'!I33+'Phase 2 Costs '!L32+'Phase 3 Costs'!L32+'Phase 4 Costs'!L32+'Phase 5 Costs'!L32+'Phase 6 Costs'!L32 -> 0 | E2: ='Phase 1 Costs'!M33+'Phase 2 Costs '!T32+'Phase 3 Costs'!T32+'Phase 4 Costs'!T32+'Phase 5 Costs'!T32+'Phase 6 Costs'!T32 -> 0 | F2: ='Phase 1 Costs'!Q33+'Phase 2 Costs '!AB32+'Phase 3 Costs'!AB32+'Phase 4 Costs'!AB32+'Phase 5 Costs'!AB32+'Phase 6 Costs'!AB32 -> 0 | G2: ='Phase 1 Costs'!U33+'Phase 2 Costs '!AJ32+'Phase 3 Costs'!AJ32+'Phase 4 Costs'!AJ32+'Phase 5 Costs'!AJ32+'Phase 6 Costs'!AJ32 -> 0 | H2: ='Phase 1 Costs'!Y33+'Phase 2 Costs '!AR32+'Phase 3 Costs'!AR32+'Phase 4 Costs'!AR32+'Phase 5 Costs'!AR32+'Phase 6 Costs'!AR32 -> 0
D5: Base | E5: Op1 | F5: Op2 | G5: Op3 | H5: Op4 | I5: Op5 | J5: Row Sum
B6: Total Direct Labor Hours | C6: tdlc.hrs | D6: =INDIRECT(CONCATENATE($C6,".",D$5)) -> 0 | E6: =INDIRECT(CONCATENATE($C6,".",E$5)) -> 0 | F6: =INDIRECT(CONCATENATE($C6,".",F$5)) -> 0 | G6: =INDIRECT(CONCATENATE($C6,".",G$5)) -> 0 | H6: =INDIRECT(CONCATENATE($C6,".",H$5)) -> 0 | I6: =INDIRECT(CONCATENATE($C6,".",I$5)) -> 0 | J6: =SUM(D6:I6) -> 0
B7: Total Direct Labor Costs | C7: tdlc.dlrs | D7: =INDIRECT(CONCATENATE($C7,".",D$5)) -> 0 | E7: =INDIRECT(CONCATENATE($C7,".",E$5)) -> 0 | F7: =INDIRECT(CONCATENATE($C7,".",F$5)) -> 0 | G7: =INDIRECT(CONCATENATE($C7,".",G$5)) -> 0 | H7: =INDIRECT(CONCATENATE($C7,".",H$5)) -> 0 | I7: =INDIRECT(CONCATENATE($C7,".",I$5)) -> 0 | J7: =SUM(D7:I7) -> 0
B8: Total Fringe Benefit Costs | C8: tfbc.dlrs | D8: =INDIRECT(CONCATENATE($C8,".",D$5)) -> #REF! | E8: =INDIRECT(CONCATENATE($C8,".",E$5)) -> #REF! | F8: =INDIRECT(CONCATENATE($C8,".",F$5)) -> #REF! | G8: =INDIRECT(CONCATENATE($C8,".",G$5)) -> #REF! | H8: =INDIRECT(CONCATENATE($C8,".",H$5)) -> #REF! | I8: =INDIRECT(CONCATENATE($C8,".",I$5)) -> #REF! | J8: =SUM(D8:I8) -> #REF!
B9: Total Labor Overhead Costs | C9: tloc.dlrs | D9: =INDIRECT(CONCATENATE($C9,".",D$5)) -> #REF! | E9: =INDIRECT(CONCATENATE($C9,".",E$5)) -> #REF! | F9: =INDIRECT(CONCATENATE($C9,".",F$5)) -> #REF! | G9: =INDIRECT(CONCATENATE($C9,".",G$5)) -> #REF! | H9: =INDIRECT(CONCATENATE($C9,".",H$5)) -> #REF! | I9: =INDIRECT(CONCATENATE($C9,".",I$5)) -> #REF! | J9: =SUM(D9:I9) -> #REF!
B10: Total Subcontract Costs | C10: tsc.dlrs | D10: =INDIRECT(CONCATENATE($C10,".",D$5)) -> 0 | E10: =INDIRECT(CONCATENATE($C10,".",E$5)) -> 0 | F10: =INDIRECT(CONCATENATE($C10,".",F$5)) -> 0 | G10: =INDIRECT(CONCATENATE($C10,".",G$5)) -> 0 | H10: =INDIRECT(CONCATENATE($C10,".",H$5)) -> 0 | I10: =INDIRECT(CONCATENATE($C10,".",I$5)) -> 0 | J10: =SUM(D10:I10) -> 0
B11: Total Consultant Costs | C11: tcc.dlrs | D11: =INDIRECT(CONCATENATE($C11,".",D$5)) -> 0 | E11: =INDIRECT(CONCATENATE($C11,".",E$5)) -> 0 | F11: =INDIRECT(CONCATENATE($C11,".",F$5)) -> 0 | G11: =INDIRECT(CONCATENATE($C11,".",G$5)) -> 0 | H11: =INDIRECT(CONCATENATE($C11,".",H$5)) -> 0 | I11: =INDIRECT(CONCATENATE($C11,".",I$5)) -> 0 | J11: =SUM(D11:I11) -> 0
B12: Total Other Direct Costs | C12: todc.dlrs | D12: =INDIRECT(CONCATENATE($C12,".",D$5)) -> 0 | E12: =INDIRECT(CONCATENATE($C12,".",E$5)) -> 0 | F12: =INDIRECT(CONCATENATE($C12,".",F$5)) -> 0 | G12: =INDIRECT(CONCATENATE($C12,".",G$5)) -> 0 | H12: =INDIRECT(CONCATENATE($C12,".",H$5)) -> 0 | I12: =INDIRECT(CONCATENATE($C12,".",I$5)) -> 0 | J12: =SUM(D12:I12) -> 0
B13: Total Material Handling Costs | C13: tmhc.dlrs | D13: =INDIRECT(CONCATENATE($C13,".",D$5)) -> 0 | E13: =INDIRECT(CONCATENATE($C13,".",E$5)) -> 0 | F13: =INDIRECT(CONCATENATE($C13,".",F$5)) -> 0 | G13: =INDIRECT(CONCATENATE($C13,".",G$5)) -> 0 | H13: =INDIRECT(CONCATENATE($C13,".",H$5)) -> 0 | I13: =INDIRECT(CONCATENATE($C13,".",I$5)) -> 0 | J13: =SUM(D13:I13) -> 0
B14: Subtotal Costs | C14: sc.dlrs | D14: =INDIRECT(CONCATENATE($C14,".",D$5)) -> 0 | E14: =INDIRECT(CONCATENATE($C14,".",E$5)) -> 0 | F14: =INDIRECT(CONCATENATE($C14,".",F$5)) -> 0 | G14: =INDIRECT(CONCATENATE($C14,".",G$5)) -> 0 | H14: =INDIRECT(CONCATENATE($C14,".",H$5)) -> 0 | I14: =INDIRECT(CONCATENATE($C14,".",I$5)) -> 0 | J14: =SUM(D14:I14) -> 0
B15: Total G&A Costs | C15: tgac.dlrs | D15: =INDIRECT(CONCATENATE($C15,".",D$5)) -> 0 | E15: =INDIRECT(CONCATENATE($C15,".",E$5)) -> 0 | F15: =INDIRECT(CONCATENATE($C15,".",F$5)) -> 0 | G15: =INDIRECT(CONCATENATE($C15,".",G$5)) -> 0 | H15: =INDIRECT(CONCATENATE($C15,".",H$5)) -> 0 | I15: =INDIRECT(CONCATENATE($C15,".",I$5)) -> 0 | J15: =SUM(D15:I15) -> 0
B16: Total Cost of Money | C16: tcm.dlrs | D16: =INDIRECT(CONCATENATE($C16,".",D$5)) -> 0 | E16: =INDIRECT(CONCATENATE($C16,".",E$5)) -> 0 | F16: =INDIRECT(CONCATENATE($C16,".",F$5)) -> 0 | G16: =INDIRECT(CONCATENATE($C16,".",G$5)) -> 0 | H16: =INDIRECT(CONCATENATE($C16,".",H$5)) -> 0 | I16: =INDIRECT(CONCATENATE($C16,".",I$5)) -> 0 | J16: =SUM(D16:I16) -> 0
B17: Fixed Fee | C17: ff.dlrs | D17: =INDIRECT(CONCATENATE($C17,".",D$5)) -> #REF! | E17: =INDIRECT(CONCATENATE($C17,".",E$5)) -> #REF! | F17: =INDIRECT(CONCATENATE($C17,".",F$5)) -> #REF! | G17: =INDIRECT(CONCATENATE($C17,".",G$5)) -> #REF! | H17: =INDIRECT(CONCATENATE($C17,".",H$5)) -> #REF! | I17: =INDIRECT(CONCATENATE($C17,".",I$5)) -> #REF! | J17: =SUM(D17:I17) -> #REF!
B18: Total Estimated Costs Plus Fixed Fee | C18: tecpff.dlrs | D18: =INDIRECT(CONCATENATE($C18,".",D$5)) -> 0 | E18: =INDIRECT(CONCATENATE($C18,".",E$5)) -> 0 | F18: =INDIRECT(CONCATENATE($C18,".",F$5)) -> 0 | G18: =INDIRECT(CONCATENATE($C18,".",G$5)) -> 0 | H18: =INDIRECT(CONCATENATE($C18,".",H$5)) -> 0 | I18: =INDIRECT(CONCATENATE($C18,".",I$5)) -> 0
B19: Column Totals | D19: =SUM(D7:D13)+SUM(D15:D17) -> #REF! | E19: =SUM(E7:E13)+SUM(E15:E17) -> #REF! | F19: =SUM(F7:F13)+SUM(F15:F17) -> #REF! | G19: =SUM(G7:G13)+SUM(G15:G17) -> #REF! | H19: =SUM(H7:H13)+SUM(H15:H17) -> #REF! | I19: =SUM(I7:I13)+SUM(I15:I17) -> #REF! | J19: =SUM(J7:J13)+SUM(J15:J17) -> #REF!
E21: Sum of Column Totals ($) | F21: =SUM(D19:I19) -> #REF!
E22: Sum of Row Totals ($) | F22: =J19 -> #REF!
E23: COLUMN TOTALS - ROW TOTALS | F23: =F21-F22 -> #REF! | G23: This should be $0. If not, research is needed.

Sheet Labor Rates
B2: =General!D4 -> Name | E2: PROPOSER LABOR RATES
B5: DO THIS SECOND. | C5: DO THIS THIRD. | D5: DO THIS FIRST. | F5: =Period1_Label -> FY 1 | G5: =Period2_Label -> FY 2 | I5: =Period3_Label -> FY 3 | K5: =Period4_Label -> FY 4 | M5: =Period5_Label -> FY 5 | O5: =Period6_Label -> FY 6 | Q5: Basis of Labor Rate
B6: Pick-List. Click on each Cell for which there is a person named and then click on the arrow in right bottom corner and choose from the list. | C6: Pick-List. Click on each Cell for which there is a person named and then click on the arrow in right bottom corner and choose from the list. | D6: Open Text. List name and position of each person assigned to this project. Then identify Labor Group and Labor Category to the left. | F6: Fully Loaded Rate | G6: Labor Escalation Rate | H6: Calculated | I6: Labor Escalation Rate | J6: Calculated | K6: Labor Escalation Rate | L6: Calculated | M6: Labor Escalation Rate | N6: Calculated | O6: Labor Escalation Rate | P6: Calculated
B7: Required ARPA-H Labor Group | C7: Required ARPA-H Labor Category | D7: Position Title | E7: Full Name | H7: Fully Loaded Rate | J7: Fully Loaded Rate | L7: Fully Loaded Rate | N7: Fully Loaded Rate | P7: Fully Loaded Rate | Q7: (Example: FPRA, Individual Payrate, Average for Job Category, etc.)
F8: 0 | G8: 0 | H8: =F8*(1+G8) -> 0 | I8: 0 | J8: =H8*(1+I8) -> 0 | K8: 0 | L8: =J8*(1+K8) -> 0 | M8: 0 | N8: =L8*(1+M8) -> 0 | O8: 0 | P8: =N8*(1+O8) -> 0
C9: =IF(ISBLANK(D9),"","Select an ARPA-H Category") | F9: 0 | G9: 0 | H9: =F9*(1+G9) -> 0 | I9: 0 | J9: =H9*(1+I9) -> 0 | K9: 0 | L9: =J9*(1+K9) -> 0 | M9: 0 | N9: =L9*(1+M9) -> 0 | O9: 0 | P9: =N9*(1+O9) -> 0
C10: =IF(ISBLANK(D10),"","Select an ARPA-H Category") | F10: 0 | G10: 0 | H10: =F10*(1+G10) -> 0 | I10: 0 | J10: =H10*(1+I10) -> 0 | K10: 0 | L10: =J10*(1+K10) -> 0 | M10: 0 | N10: =L10*(1+M10) -> 0 | O10: 0 | P10: =N10*(1+O10) -> 0
C11: =IF(ISBLANK(D11),"","Select an ARPA-H Category") | F11: 0 | G11: 0 | H11: =F11*(1+G11) -> 0 | I11: 0 | J11: =H11*(1+I11) -> 0 | K11: 0 | L11: =J11*(1+K11) -> 0 | M11: 0 | N11: =L11*(1+M11) -> 0 | O11: 0 | P11: =N11*(1+O11) -> 0
C12: =IF(ISBLANK(D12),"","Select an ARPA-H Category") | F12: 0 | G12: 0 | H12: =F12*(1+G12) -> 0 | I12: 0 | J12: =H12*(1+I12) -> 0 | K12: 0 | L12: =J12*(1+K12) -> 0 | M12: 0 | N12: =L12*(1+M12) -> 0 | O12: 0 | P12: =N12*(1+O12) -> 0
C13: =IF(ISBLANK(D13),"","Select an ARPA-H Category") | F13: 0 | G13: 0 | H13: =F13*(1+G13) -> 0 | I13: 0 | J13: =H13*(1+I13) -> 0 | K13: 0 | L13: =J13*(1+K13) -> 0 | M13: 0 | N13: =L13*(1+M13) -> 0 | O13: 0 | P13: =N13*(1+O13) -> 0
C14: =IF(ISBLANK(D14),"","Select an ARPA-H Category") | F14: 0 | G14: 0 | H14: =F14*(1+G14) -> 0 | I14: 0 | J14: =H14*(1+I14) -> 0 | K14: 0 | L14: =J14*(1+K14) -> 0 | M14: 0 | N14: =L14*(1+M14) -> 0 | O14: 0 | P14: =N14*(1+O14) -> 0
C15: =IF(ISBLANK(D15),"","Select an ARPA-H Category") | F15: 0 | G15: 0 | H15: =F15*(1+G15) -> 0 | I15: 0 | J15: =H15*(1+I15) -> 0 | K15: 0 | L15: =J15*(1+K15) -> 0 | M15: 0 | N15: =L15*(1+M15) -> 0 | O15: 0 | P15: =N15*(1+O15) -> 0
C16: =IF(ISBLANK(D16),"","Select an ARPA-H Category") | F16: 0 | G16: 0 | H16: =F16*(1+G16) -> 0 | I16: 0 | J16: =H16*(1+I16) -> 0 | K16: 0 | L16: =J16*(1+K16) -> 0 | M16: 0 | N16: =L16*(1+M16) -> 0 | O16: 0 | P16: =N16*(1+O16) -> 0
C17: =IF(ISBLANK(D17),"","Select an ARPA-H Category") | F17: 0 | G17: 0 | H17: =F17*(1+G17) -> 0 | I17: 0 | J17: =H17*(1+I17) -> 0 | K17: 0 | L17: =J17*(1+K17) -> 0 | M17: 0 | N17: =L17*(1+M17) -> 0 | O17: 0 | P17: =N17*(1+O17) -> 0
C18: =IF(ISBLANK(D18),"","Select an ARPA-H Category") | F18: 0 | G18: 0 | H18: =F18*(1+G18) -> 0 | I18: 0 | J18: =H18*(1+I18) -> 0 | K18: 0 | L18: =J18*(1+K18) -> 0 | M18: 0 | N18: =L18*(1+M18) -> 0 | O18: 0 | P18: =N18*(1+O18) -> 0
C19: =IF(ISBLANK(D19),"","Select an ARPA-H Category") | F19: 0 | G19: 0 | H19: =F19*(1+G19) -> 0 | I19: 0 | J19: =H19*(1+I19) -> 0 | K19: 0 | L19: =J19*(1+K19) -> 0 | M19: 0 | N19: =L19*(1+M19) -> 0 | O19: 0 | P19: =N19*(1+O19) -> 0
C20: =IF(ISBLANK(D20),"","Select an ARPA-H Category") | F20: 0 | G20: 0 | H20: =F20*(1+G20) -> 0 | I20: 0 | J20: =H20*(1+I20) -> 0 | K20: 0 | L20: =J20*(1+K20) -> 0 | M20: 0 | N20: =L20*(1+M20) -> 0 | O20: 0 | P20: =N20*(1+O20) -> 0
... C31: =IF(ISBLANK(D31),"","Select an ARPA-H Category") | F31: 0 | G31: 0 | H31: =F31*(1+G31) -> 0 | I31: 0 | J31: =H31*(1+I31) -> 0 | K31: 0 | L31: =J31*(1+K31) -> 0 | M31: 0 | N31: =L31*(1+M31) -> 0 | O31: 0 | P31: =N31*(1+O31) -> 0
B32: Insert additional Labor Category rows above this line. Copy formulas from adjacent rows to ensure calculations are carried forward. You must also add lines to the "Phase X Costs" and "Total Amount" sheets to match any data added here.
B34: Instructions: | C34: • If the rates have been approved/negotiated by a government agency, provide a copy of the memorandum/agreement (FPRA/FPRR). • If the rates have not been approved/negotiated, provide sufficient detail to enable a determination of allowability, allocability and reasonableness of the allocation bases and how the rates are calculated. This information can be provided in your cost volume or add another worksheet tab in this spreadsheet to show calculations. • If composite rates are used, provide the calculations used in deriving the composite rates in your cost volume or add another worksheet tab in this spreadsheet to show calculations. • If an FPRA is not available, provide back-up documentation for labor rates (e.g., current payroll records)
B35: Note 1: | C35: You must have set the Organization's "Business Type" on the Proposer Constants worksheet to populate the list of ARPA-H Labor Categories
B36: Note 2: | C36: Each proposed Proposer Labor Category must be associated with an ARPA-H Labor Category (columns B and C above). Choose the best fit using the descriptions below. Proposer's should then place their own labor category title and name of proposed personnel as they normally would (columns D and E above).
C38: Labor Category Level | D38: Description
C39: Junior | D39: Entry-level/Junior
C40: Mid | D40: Mid-level/Journeyman
C41: Senior | D41: Senior Level
C42: Principal | D42: Team Lead/Subject Matter Expert
C44: Description Definitions | D44: Consider experience, education, and expertise when selecting a labor category level.
C45: JUNIOR | D45: The junior-level or entry-level position assists more senior positions and may perform tasks and duties under supervision. This level performs work that requires practical experience and training, and applies fundamental concepts, processes, practices, and procedures on technical assignments.
C46: MID | D46: The journeyman or mid-level position usually performs tasks and duties independently. This position displays and applies intermediate expertise in several complex work assignments which may require originality, innovation, or independent thinking to accomplish. The journeyman or mid-level position contributes to deliverables and performance metrics and is afforded some flexibility to develop or design methods, processes, or solutions to problems.
C47: SENIOR | D47: The senior-level position works on high-visibility or mission-critical aspects of programs or projects and performs tasks and duties independently. This position may oversee or supervise or be responsible for the work of subordinate or less senior positions assigned to programs or projects. The senior-level position displays and applies mastery or distinguished expertise in critical tasks and high-impact assignments. This position leads, manages, plans, and functions as the technical or subject matter expert across multiple programs or projects.
C48: PRINCIPAL | D48: The Principal position leads or manages the entire program or project. The Principal is often a person who is considered to be a leader in a scientific or technical field.

Sheet Phase 1 Costs
A2: Cost Proposal - Phase 1 (see instructions below) | C2: Proposed PoP as "MM/YY to MM/YY"
A4: Proposer | B4: =General!D4 -> Name
A5: Prime Proposer | B5: =General!D5 -> Name
E6: =Period1_Label -> FY 1 | I6: =Period2_Label -> FY 2 | M6: =Period3_Label -> FY 3 | Q6: =Period4_Label -> FY 4 | U6: =Period5_Label -> FY 5 | Y6: =Period6_Label -> FY 6 | AC6: TOTALS
A7: DIRECT LABOR | E7: =CONCATENATE(TEXT('Proposer Constants'!C14,"MM/DD/YY")," to ",TEXT('Proposer Constants'!C15,"MM/DD/YY")) -> 06/01/25 to 05/31/26 | I7: =CONCATENATE(TEXT('Proposer Constants'!D14,"MM/DD/YY")," to ",TEXT('Proposer Constants'!D15,"MM/DD/YY")) -> 06/01/26 to 05/31/27 | M7: =CONCATENATE(TEXT('Proposer Constants'!E14,"MM/DD/YY")," to ",TEXT('Proposer Constants'!E15,"MM/DD/YY")) -> 06/01/27 to 05/31/28 | Q7: =CONCATENATE(TEXT('Proposer Constants'!F14,"MM/DD/YY")," to ",TEXT('Proposer Constants'!F15,"MM/DD/YY")) -> 06/01/28 to 05/31/29 | U7: =CONCATENATE(TEXT('Proposer Constants'!G14,"MM/DD/YY")," to ",TEXT('Proposer Constants'!G15,"MM/DD/YY")) -> 06/01/29 to 05/31/30 | Y7: =CONCATENATE(TEXT('Proposer Constants'!H14,"MM/DD/YY")," to ",TEXT('Proposer Constants'!H15,"MM/DD/YY")) -> 06/01/30 to 05/31/31 | AC7: X-Months (See Note 2)
A8: Personnel Position Titles | C8: Names (Last, First) | E8: Hours | F8: Hourly Labor Rate | G8: Total $ | I8: Hours | J8: Hourly Labor Rate | K8: Total $ | M8: Hours | N8: Hourly Labor Rate | O8: Total $ | Q8: Hours | R8: Hourly Labor Rate | S8: Total $ | U8: Hours | V8: Hourly Labor Rate | W8: Total $ | Y8: Hours | Z8: Hourly Labor Rate | AA8: Total $ | AC8: Total DL Hours | AD8: Total Labor Cost
A9: =IF(ISBLANK('Labor Rates'!D8),"",'Labor Rates'!D8) | C9: =IF(ISBLANK('Labor Rates'!E8),"",'Labor Rates'!E8) | E9: 0 | F9: ='Labor Rates'!F8 -> 0 | G9: =E9*F9 -> 0 | I9: 0 | J9: ='Labor Rates'!H8 -> 0 | K9: =I9*J9 -> 0 | M9: 0 | N9: ='Labor Rates'!J8 -> 0 | O9: =M9*N9 -> 0 | Q9: 0 | R9: ='Labor Rates'!L8 -> 0 | S9: =Q9*R9 -> 0 | U9: 0 | V9: ='Labor Rates'!N8 -> 0 | W9: =U9*V9 -> 0 | Y9: 0 | Z9: ='Labor Rates'!P8 -> 0 | AA9: =Y9*Z9 -> 0 | AC9: =E9+I9+M9+Q9+U9+Y9 -> 0 | AD9: =G9+K9+O9+S9+W9+AA9 -> 0
A10: =IF(ISBLANK('Labor Rates'!D9),"",'Labor Rates'!D9) | C10: =IF(ISBLANK('Labor Rates'!E9),"",'Labor Rates'!E9) | E10: 0 | F10: ='Labor Rates'!F9 -> 0 | G10: =E10*F10 -> 0 | I10: 0 | J10: ='Labor Rates'!H9 -> 0 | K10: =I10*J10 -> 0 | M10: 0 | N10: ='Labor Rates'!J9 -> 0 | O10: =M10*N10 -> 0 | Q10: 0 | R10: ='Labor Rates'!L9 -> 0 | S10: =Q10*R10 -> 0 | U10: 0 | V10: ='Labor Rates'!N9 -> 0 | W10: =U10*V10 -> 0 | Y10: 0 | Z10: ='Labor Rates'!P9 -> 0 | AA10: =Y10*Z10 -> 0 | AC10: =E10+I10+M10+Q10+U10+Y10 -> 0 | AD10: =G10+K10+O10+S10+W10+AA10 -> 0
A11: =IF(ISBLANK('Labor Rates'!D10),"",'Labor Rates'!D10) | C11: =IF(ISBLANK('Labor Rates'!E10),"",'Labor Rates'!E10) | E11: 0 | F11: ='Labor Rates'!F10 -> 0 | G11: =E11*F11 -> 0 | I11: 0 | J11: ='Labor Rates'!H10 -> 0 | K11: =I11*J11 -> 0 | M11: 0 | N11: ='Labor Rates'!J10 -> 0 | O11: =M11*N11 -> 0 | Q11: 0 | R11: ='Labor Rates'!L10 -> 0 | S11: =Q11*R11 -> 0 | U11: 0 | V11: ='Labor Rates'!N10 -> 0 | W11: =U11*V11 -> 0 | Y11: 0 | Z11: ='Labor Rates'!P10 -> 0 | AA11: =Y11*Z11 -> 0 | AC11: =E11+I11+M11+Q11+U11+Y11 -> 0 | AD11: =G11+K11+O11+S11+W11+AA11 -> 0
A12: =IF(ISBLANK('Labor Rates'!D11),"",'Labor Rates'!D11) | C12: =IF(ISBLANK('Labor Rates'!E11),"",'Labor Rates'!E11) | E12: 0 | F12: ='Labor Rates'!F11 -> 0 | G12: =E12*F12 -> 0 | I12: 0 | J12: ='Labor Rates'!H11 -> 0 | K12: =I12*J12 -> 0 | M12: 0 | N12: ='Labor Rates'!J11 -> 0 | O12: =M12*N12 -> 0 | Q12: 0 | R12: ='Labor Rates'!L11 -> 0 | S12: =Q12*R12 -> 0 | U12: 0 | V12: ='Labor Rates'!N11 -> 0 | W12: =U12*V12 -> 0 | Y12: 0 | Z12: ='Labor Rates'!P11 -> 0 | AA12: =Y12*Z12 -> 0 | AC12: =E12+I12+M12+Q12+U12+Y12 -> 0 | AD12: =G12+K12+O12+S12+W12+AA12 -> 0
A13: =IF(ISBLANK('Labor Rates'!D12),"",'Labor Rates'!D12) | C13: =IF(ISBLANK('Labor Rates'!E12),"",'Labor Rates'!E12) | E13: 0 | F13: ='Labor Rates'!F12 -> 0 | G13: =E13*F13 -> 0 | I13: 0 | J13: ='Labor Rates'!H12 -> 0 | K13: =I13*J13 -> 0 | M13: 0 | N13: ='Labor Rates'!J12 -> 0 | O13: =M13*N13 -> 0 | Q13: 0 | R13: ='Labor Rates'!L12 -> 0 | S13: =Q13*R13 -> 0 | U13: 0 | V13: ='Labor Rates'!N12 -> 0 | W13: =U13*V13 -> 0 | Y13: 0 | Z13: ='Labor Rates'!P12 -> 0 | AA13: =Y13*Z13 -> 0 | AC13: =E13+I13+M13+Q13+U13+Y13 -> 0 | AD13: =G13+K13+O13+S13+W13+AA13 -> 0
A14: =IF(ISBLANK('Labor Rates'!D13),"",'Labor Rates'!D13) | C14: =IF(ISBLANK('Labor Rates'!E13),"",'Labor Rates'!E13) | E14: 0 | F14: ='Labor Rates'!F13 -> 0 | G14: =E14*F14 -> 0 | I14: 0 | J14: ='Labor Rates'!H13 -> 0 | K14: =I14*J14 -> 0 | M14: 0 | N14: ='Labor Rates'!J13 -> 0 | O14: =M14*N14 -> 0 | Q14: 0 | R14: ='Labor Rates'!L13 -> 0 | S14: =Q14*R14 -> 0 | U14: 0 | V14: ='Labor Rates'!N13 -> 0 | W14: =U14*V14 -> 0 | Y14: 0 | Z14: ='Labor Rates'!P13 -> 0 | AA14: =Y14*Z14 -> 0 | AC14: =E14+I14+M14+Q14+U14+Y14 -> 0 | AD14: =G14+K14+O14+S14+W14+AA14 -> 0
A15: =IF(ISBLANK('Labor Rates'!D14),"",'Labor Rates'!D14) | C15: =IF(ISBLANK('Labor Rates'!E14),"",'Labor Rates'!E14) | E15: 0 | F15: ='Labor Rates'!F14 -> 0 | G15: =E15*F15 -> 0 | I15: 0 | J15: ='Labor Rates'!H14 -> 0 | K15: =I15*J15 -> 0 | M15: 0 | N15: ='Labor Rates'!J14 -> 0 | O15: =M15*N15 -> 0 | Q15: 0 | R15: ='Labor Rates'!L14 -> 0 | S15: =Q15*R15 -> 0 | U15: 0 | V15: ='Labor Rates'!N14 -> 0 | W15: =U15*V15 -> 0 | Y15: 0 | Z15: ='Labor Rates'!P14 -> 0 | AA15: =Y15*Z15 -> 0 | AC15: =E15+I15+M15+Q15+U15+Y15 -> 0 | AD15: =G15+K15+O15+S15+W15+AA15 -> 0
A16: =IF(ISBLANK('Labor Rates'!D15),"",'Labor Rates'!D15) | C16: =IF(ISBLANK('Labor Rates'!E15),"",'Labor Rates'!E15) | E16: 0 | F16: ='Labor Rates'!F15 -> 0 | G16: =E16*F16 -> 0 | I16: 0 | J16: ='Labor Rates'!H15 -> 0 | K16: =I16*J16 -> 0 | M16: 0 | N16: ='Labor Rates'!J15 -> 0 | O16: =M16*N16 -> 0 | Q16: 0 | R16: ='Labor Rates'!L15 -> 0 | S16: =Q16*R16 -> 0 | U16: 0 | V16: ='Labor Rates'!N15 -> 0 | W16: =U16*V16 -> 0 | Y16: 0 | Z16: ='Labor Rates'!P15 -> 0 | AA16: =Y16*Z16 -> 0 | AC16: =E16+I16+M16+Q16+U16+Y16 -> 0 | AD16: =G16+K16+O16+S16+W16+AA16 -> 0
A17: =IF(ISBLANK('Labor Rates'!D16),"",'Labor Rates'!D16) | C17: =IF(ISBLANK('Labor Rates'!E16),"",'Labor Rates'!E16) | E17: 0 | F17: ='Labor Rates'!F16 -> 0 | G17: =E17*F17 -> 0 | I17: 0 | J17: ='Labor Rates'!H16 -> 0 | K17: =I17*J17 -> 0 | M17: 0 | N17: ='Labor Rates'!J16 -> 0 | O17: =M17*N17 -> 0 | Q17: 0 | R17: ='Labor Rates'!L16 -> 0 | S17: =Q17*R17 -> 0 | U17: 0 | V17: ='Labor Rates'!N16 -> 0 | W17: =U17*V17 -> 0 | Y17: 0 | Z17: ='Labor Rates'!P16 -> 0 | AA17: =Y17*Z17 -> 0 | AC17: =E17+I17+M17+Q17+U17+Y17 -> 0 | AD17: =G17+K17+O17+S17+W17+AA17 -> 0
A18: =IF(ISBLANK('Labor Rates'!D17),"",'Labor Rates'!D17) | C18: =IF(ISBLANK('Labor Rates'!E17),"",'Labor Rates'!E17) | E18: 0 | F18: ='Labor Rates'!F17 -> 0 | G18: =E18*F18 -> 0 | I18: 0 | J18: ='Labor Rates'!H17 -> 0 | K18: =I18*J18 -> 0 | M18: 0 | N18: ='Labor Rates'!J17 -> 0 | O18: =M18*N18 -> 0 | Q18: 0 | R18: ='Labor Rates'!L17 -> 0 | S18: =Q18*R18 -> 0 | U18: 0 | V18: ='Labor Rates'!N17 -> 0 | W18: =U18*V18 -> 0 | Y18: 0 | Z18: ='Labor Rates'!P17 -> 0 | AA18: =Y18*Z18 -> 0 | AC18: =E18+I18+M18+Q18+U18+Y18 -> 0 | AD18: =G18+K18+O18+S18+W18+AA18 -> 0
A19: =IF(ISBLANK('Labor Rates'!D18),"",'Labor Rates'!D18) | C19: =IF(ISBLANK('Labor Rates'!E18),"",'Labor Rates'!E18) | E19: 0 | F19: ='Labor Rates'!F18 -> 0 | G19: =E19*F19 -> 0 | I19: 0 | J19: ='Labor Rates'!H18 -> 0 | K19: =I19*J19 -> 0 | M19: 0 | N19: ='Labor Rates'!J18 -> 0 | O19: =M19*N19 -> 0 | Q19: 0 | R19: ='Labor Rates'!L18 -> 0 | S19: =Q19*R19 -> 0 | U19: 0 | V19: ='Labor Rates'!N18 -> 0 | W19: =U19*V19 -> 0 | Y19: 0 | Z19: ='Labor Rates'!P18 -> 0 | AA19: =Y19*Z19 -> 0 | AC19: =E19+I19+M19+Q19+U19+Y19 -> 0 | AD19: =G19+K19+O19+S19+W19+AA19 -> 0
A20: =IF(ISBLANK('Labor Rates'!D19),"",'Labor Rates'!D19) | C20: =IF(ISBLANK('Labor Rates'!E19),"",'Labor Rates'!E19) | E20: 0 | F20: ='Labor Rates'!F19 -> 0 | G20: =E20*F20 -> 0 | I20: 0 | J20: ='Labor Rates'!H19 -> 0 | K20: =I20*J20 -> 0 | M20: 0 | N20: ='Labor Rates'!J19 -> 0 | O20: =M20*N20 -> 0 | Q20: 0 | R20: ='Labor Rates'!L19 -> 0 | S20: =Q20*R20 -> 0 | U20: 0 | V20: ='Labor Rates'!N19 -> 0 | W20: =U20*V20 -> 0 | Y20: 0 | Z20: ='Labor Rates'!P19 -> 0 | AA20: =Y20*Z20 -> 0 | AC20: =E20+I20+M20+Q20+U20+Y20 -> 0 | AD20: =G20+K20+O20+S20+W20+AA20 -> 0
... A32: =IF(ISBLANK('Labor Rates'!D31),"",'Labor Rates'!D31) | C32: =IF(ISBLANK('Labor Rates'!E31),"",'Labor Rates'!E31) | E32: 0 | F32: ='Labor Rates'!F31 -> 0 | G32: =E32*F32 -> 0 | I32: 0 | J32: ='Labor Rates'!H31 -> 0 | K32: =I32*J32 -> 0 | M32: 0 | N32: ='Labor Rates'!J31 -> 0 | O32: =M32*N32 -> 0 | Q32: 0 | R32: ='Labor Rates'!L31 -> 0 | S32: =Q32*R32 -> 0 | U32: 0 | V32: ='Labor Rates'!N31 -> 0 | W32: =U32*V32 -> 0 | Y32: 0 | Z32: ='Labor Rates'!P31 -> 0 | AA32: =Y32*Z32 -> 0 | AC32: =E32+I32+M32+Q32+U32+Y32 -> 0 | AD32: =G32+K32+O32+S32+W32+AA32 -> 0
C33: Direct Labor Hours & Dollars | E33: =SUM(E9:E32) -> 0 | F33: Total Labor | G33: =SUM(G9:G32) -> 0 | I33: =SUM(I9:I32) -> 0 | J33: Total Labor | K33: =SUM(K9:K32) -> 0 | M33: =SUM(M9:M32) -> 0 | N33: Total Labor | O33: =SUM(O9:O32) -> 0 | Q33: =SUM(Q9:Q32) -> 0 | R33: Total Labor | S33: =SUM(S9:S32) -> 0 | U33: =SUM(U9:U32) -> 0 | V33: Total Labor | W33: =SUM(W9:W32) -> 0 | Y33: =SUM(Y9:Y32) -> 0 | Z33: Total Labor | AA33: =SUM(AA9:AA32) -> 0 | AC33: =SUM(AC9:AC32) -> 0 | AD33: =SUM(AD9:AD32) -> 0
A35: Subproposer/Inter-Organizational Transfer | G35: Subproposers | K35: Subproposers | O35: Subproposers | S35: Subproposers | W35: Subproposers | AA35: Subproposers | AD35: Subproposer Costs
A36: Subproposer- #01 | C36: Provide details in Subproposer Tab | G36: 0 | K36: 0 | O36: 0 | S36: 0 | W36: 0 | AA36: 0 | AD36: =G36+K36+O36+S36+W36+AA36 -> 0
A37: Subproposer- #02 | C37: Provide details in Subproposer Tab | G37: 0 | K37: 0 | O37: 0 | S37: 0 | W37: 0 | AA37: 0 | AD37: =G37+K37+O37+S37+W37+AA37 -> 0
A38: Subproposer- #03 | C38: Provide details in Subproposer Tab | G38: 0 | K38: 0 | O38: 0 | S38: 0 | W38: 0 | AA38: 0 | AD38: =G38+K38+O38+S38+W38+AA38 -> 0
A39: Insert line(s) for additional Subproposers | C39: Provide details in Subproposer Tab | G39: 0 | K39: 0 | O39: 0 | S39: 0 | W39: 0 | AA39: 0 | AD39: =G39+K39+O39+S39+W39+AA39 -> 0
A40: Subproposers | G40: =SUM(G35:G39) -> 0 | K40: =SUM(K35:K39) -> 0 | O40: =SUM(O35:O39) -> 0 | S40: =SUM(S35:S39) -> 0 | W40: =SUM(W35:W39) -> 0 | AA40: =SUM(AA35:AA39) -> 0 | AD40: =G40+K40+O40+S40+W40+AA40 -> 0
A42: Consultants | E42: Hours | F42: Hourly Rate | G42: Total Consultants | I42: Hours | J42: Hourly Rate | K42: Total Consultants | M42: Hours | N42: Hourly Rate | O42: Total Consultants | Q42: Hours | R42: Hourly Rate | S42: Total Consultants | U42: Hours | V42: Hourly Rate | W42: Total Consultants | Y42: Total | Z42: Hourly Rate | AA42: Total Consultants | AC42: Hours | AD42: Total Consultant Labor Costs
A43: Consultant Name - #01 | C43: Provide details in Consultant Tab | E43: 0 | F43: 0 | G43: =E43*F43 -> 0 | I43: 0 | J43: 0 | K43: =I43*J43 -> 0 | M43: 0 | N43: 0 | O43: =M43*N43 -> 0 | Q43: 0 | R43: 0 | S43: =Q43*R43 -> 0 | U43: 0 | V43: 0 | W43: =U43*V43 -> 0 | Y43: 0 | Z43: 0 | AA43: =Y43*Z43 -> 0 | AC43: =SUM(E43,I43,M43,Q43,U43,Y43) -> 0 | AD43: =G43+K43+O43+S43+W43+AA43 -> 0
A44: Consultant Name - #02 | C44: Provide details in Consultant Tab | E44: 0 | F44: 0 | G44: =E45*F44 -> 0 | I44: 0 | J44: 0 | K44: =I44*J44 -> 0 | M44: 0 | N44: 0 | O44: =M44*N44 -> 0 | Q44: 0 | R44: 0 | S44: =Q44*R44 -> 0 | U44: 0 | V44: 0 | W44: =U44*V44 -> 0 | Y44: 0 | Z44: 0 | AA44: =Y44*Z44 -> 0 | AC44: =SUM(E44,I44,M44,Q44,U44,Y44) -> 0 | AD44: =G44+K44+O44+S44+W44+AA44 -> 0
A45: Consultant Name - #03 | C45: Provide details in Consultant Tab | E45: 0 | F45: 0 | G45: =E46*F45 -> 0 | I45: 0 | J45: 0 | K45: =I45*J45 -> 0 | M45: 0 | N45: 0 | O45: =M45*N45 -> 0 | Q45: 0 | R45: 0 | S45: =Q45*R45 -> 0 | U45: 0 | V45: 0 | W45: =U45*V45 -> 0 | Y45: 0 | Z45: 0 | AA45: =Y45*Z45 -> 0 | AC45: =SUM(E45,I45,M45,Q45,U45,Y45) -> 0 | AD45: =G45+K45+O45+S45+W45+AA45 -> 0
A46: Insert line(s) for additional Consultants | C46: Provide details in Consultant Tab | E46: 0 | F46: 0 | G46: =E46*F46 -> 0 | I46: 0 | J46: 0 | K46: =I46*J46 -> 0 | M46: 0 | N46: 0 | O46: =M46*N46 -> 0 | Q46: 0 | R46: 0 | S46: =Q46*R46 -> 0 | U46: 0 | V46: 0 | W46: =U46*V46 -> 0 | Y46: 0 | Z46: 0 | AA46: =Y46*Z46 -> 0 | AC46: =SUM(E46,I46,M46,Q46,U46,Y46) -> 0 | AD46: =G46+K46+O46+S46+W46+AA46 -> 0
A47: Consultants | E47: =SUM(E43:E46) -> 0 | G47: =SUM(G42:G46) -> 0 | I47: =SUM(I43:I46) -> 0 | K47: =SUM(K42:K46) -> 0 | M47: =SUM(M43:M46) -> 0 | O47: =SUM(O42:O46) -> 0 | Q47: =SUM(Q43:Q46) -> 0 | S47: =SUM(S42:S46) -> 0 | U47: =SUM(U43:U46) -> 0 | W47: =SUM(W42:W46) -> 0 | Y47: =SUM(Y43:Y46) -> 0 | AA47: =SUM(AA42:AA46) -> 0 | AC47: =SUM(AC43:AC46) -> 0 | AD47: =G47+K47+O47+S47+W47+AA47 -> 0
A49: Other Direct Costs | G49: ODCs | K49: ODCs | O49: ODCs | S49: ODCs | W49: Total | AA49: ODCs | AD49: ODCs
A50: Materials/Supplies | C50: Provide details in Materials Tab | G50: 0 | K50: 0 | O50: 0 | S50: 0 | W50: 0 | AA50: 0 | AD50: =G50+K50+O50+S50+W50+AA50 -> 0
A51: Equipment | C51: Provide details in Equip. Tab | G51: 0 | K51: 0 | O51: 0 | S51: 0 | W51: 0 | AA51: 0 | AD51: =G51+K51+O51+S51+W51+AA51 -> 0
A52: Travel | C52: Provide details in Travel Tab | G52: 0 | K52: 0 | O52: 0 | S52: 0 | W52: 0 | AA52: 0 | AD52: =G52+K52+O52+S52+W52+AA52 -> 0
A53: Insert line(s) for other types of ODCs | C53: Provide details in ODC Tab | G53: 0 | K53: 0 | O53: 0 | S53: 0 | W53: 0 | AA53: 0 | AD53: =G53+K53+O53+S53+W53+AA53 -> 0
A54: Other Direct Costs | G54: =SUM(G49:G53) -> 0 | K54: =SUM(K49:K53) -> 0 | O54: =SUM(O49:O53) -> 0 | S54: =SUM(S49:S53) -> 0 | W54: =SUM(W49:W53) -> 0 | AA54: =SUM(AA49:AA53) -> 0 | AD54: =G54+K54+O54+S54+W54+AA54 -> 0
A56: Material Handling (M/H O/H) | E56: 0 | F56: Rate | G56: Total M/H | I56: Base | J56: Rate | K56: Total M/H | M56: Base | N56: Rate | O56: Total M/H | Q56: Base | R56: Rate | S56: Total M/H | U56: Base | V56: Rate | W56: Total M/H | Y56: Base | Z56: Rate | AA56: Total M/H | AD56: Material Handling
A57: Insert M/H O/H rate title | E57: 0 | F57: 0 | G57: =E57*F57 -> 0 | I57: 0 | J57: 0 | K57: =I57*J57 -> 0 | M57: 0 | N57: 0 | O57: =M57*N57 -> 0 | Q57: 0 | R57: 0 | S57: =Q57*R57 -> 0 | U57: 0 | V57: 0 | W57: =U57*V57 -> 0 | Y57: 0 | Z57: 0 | AA57: =Y57*Z57 -> 0 | AD57: =G57+K57+O57+S57+W57+AA57 -> 0
...

Sheet Ph 1 Task $
B2: Phase 1 - COST BY TASK | H2: Instructions: | I2: • Insert the Tasks that you listed in the TDD Template and number appropriately. Complete all cells that are unshaded. • Ensure the quarter start/end dates align with your inputs in the SOW Template. Subtotals and totals will automatically calculate. • Add additional rows and columns if needed.
B6: =General!D4 -> Name
B7: Task Number | C7: Task Title | D7: Start Qtr (1-4) | E7: Calendar Year (XX) | F7: End Qtr (1-4) | G7: Calendar Year (XX) | H7: Total Prime Costs | I7: Team Member #1 Cost | J7: Team Member #2 Cost | K7: All Subproposers' Total Costs | L7: Task Subtotals | M7: Task Totals
B8: 1.1.X | H8: 0 | I8: 0 | J8: 0 | K8: 0 | L8: =SUM(H8:K8) -> 0
B9: 1.1.X | H9: 0 | I9: 0 | J9: 0 | K9: 0 | L9: =SUM(H9:K9) -> 0
B10: 1.1.X | H10: 0 | I10: 0 | J10: 0 | K10: 0 | L10: =SUM(H10:K10) -> 0
B11: 1.1.X | H11: 0 | I11: 0 | J11: 0 | K11: 0 | L11: =SUM(H11:K11) -> 0
B12: 1.1.X | H12: 0 | I12: 0 | J12: 0 | K12: 0 | L12: =SUM(H12:K12) -> 0
B13: 1.1.X | H13: 0 | I13: 0 | J13: 0 | K13: 0 | L13: =SUM(H13:K13) -> 0
B14: 1.1.X | H14: 0 | I14: 0 | J14: 0 | K14: 0 | L14: =SUM(H14:K14) -> 0
B15: Total Costs for Phase 1, Task 1 | H15: =SUM(H8:H14) -> 0 | I15: =SUM(I8:I14) -> 0 | J15: =SUM(J8:J14) -> 0 | K15: =SUM(K8:K14) -> 0 | M15: =SUM(H15:K15) -> 0
B18: 1.2.X | H18: 0 | I18: 0 | J18: 0 | K18: 0 | L18: =SUM(H18:K18) -> 0
B19: 1.2.X | H19: 0 | I19: 0 | J19: 0 | K19: 0 | L19: =SUM(H19:K19) -> 0
B20: 1.2.X | H20: 0 | I20: 0 | J20: 0 | K20: 0 | L20: =SUM(H20:K20) -> 0
B21: 1.2.X | H21: 0 | I21: 0 | J21: 0 | K21: 0 | L21: =SUM(H21:K21) -> 0
B22: 1.2.X | H22: 0 | I22: 0 | J22: 0 | K22: 0 | L22: =SUM(H22:K22) -> 0
B23: 1.2.X | H23: 0 | I23: 0 | J23: 0 | K23: 0 | L23: =SUM(H23:K23) -> 0
B24: 1.2.X | H24: 0 | I24: 0 | J24: 0 | K24: 0 | L24: =SUM(H24:K24) -> 0
B25: Total Costs for Phase 1, Task 2 | H25: =SUM(H18:H24) -> 0 | I25: =SUM(I18:I24) -> 0 | J25: =SUM(J18:J24) -> 0 | K25: =SUM(K18:K24) -> 0 | M25: =SUM(H25:K25) -> 0
B28: 1.3.X | H28: 0 | I28: 0 | J28: 0 | K28: 0 | L28: =SUM(H28:K28) -> 0
B29: 1.3.X | H29: 0 | I29: 0 | J29: 0 | K29: 0 | L29: =SUM(H29:K29) -> 0
B30: 1.3.X | H30: 0 | I30: 0 | J30: 0 | K30: 0 | L30: =SUM(H30:K30) -> 0
B31: 1.3.X | H31: 0 | I31: 0 | J31: 0 | K31: 0 | L31: =SUM(H31:K31) -> 0
B32: 1.3.X | H32: 0 | I32: 0 | J32: 0 | K32: 0 | L32: =SUM(H32:K32) -> 0
B33: 1.3.X | H33: 0 | I33: 0 | J33: 0 | K33: 0 | L33: =SUM(H33:K33) -> 0
B34: 1.3.X | H34: 0 | I34: 0 | J34: 0 | K34: 0 | L34: =SUM(H34:K34) -> 0
B35: Total Costs for Phase 1, Task 3 | H35: =SUM(H28:H34) -> 0 | I35: =SUM(I28:I34) -> 0 | J35: =SUM(J28:J34) -> 0 | K35: =SUM(K28:K34) -> 0 | M35: =SUM(H35:K35) -> 0
B38: 1.4.X | H38: 0 | I38: 0 | J38: 0 | K38: 0 | L38: =SUM(H38:K38) -> 0
B39: 1.4.X | H39: 0 | I39: 0 | J39: 0 | K39: 0 | L39: =SUM(H39:K39) -> 0
B40: 1.4.X | H40: 0 | I40: 0 | J40: 0 | K40: 0 | L40: =SUM(H40:K40) -> 0
B41: 1.4.X | H41: 0 | I41: 0 | J41: 0 | K41: 0 | L41: =SUM(H41:K41) -> 0
B42: 1.4.X | H42: 0 | I42: 0 | J42: 0 | K42: 0 | L42: =SUM(H42:K42) -> 0
B43: 1.4.X | H43: 0 | I43: 0 | J43: 0 | K43: 0 | L43: =SUM(H43:K43) -> 0
B44: Total Costs for Phase 1, Task 4 | H44: =SUM(H38:H43) -> 0 | I44: =SUM(I38:I43) -> 0 | J44: =SUM(J38:J43) -> 0 | K44: =SUM(K38:K43) -> 0 | M44: =SUM(H44:K44) -> 0
B47: 1.5.X | H47: 0 | I47: 0 | J47: 0 | K47: 0 | L47: =SUM(H47:K47) -> 0
B48: 1.5.X | H48: 0 | I48: 0 | J48: 0 | K48: 0 | L48: =SUM(H48:K48) -> 0
B49: 1.5.X | H49: 0 | I49: 0 | J49: 0 | K49: 0 | L49: =SUM(H49:K49) -> 0
B50: 1.5.X | H50: 0 | I50: 0 | J50: 0 | K50: 0 | L50: =SUM(H50:K50) -> 0
B51: 1.5.X | H51: 0 | I51: 0 | J51: 0 | K51: 0 | L51: =SUM(H51:K51) -> 0
B52: 1.5.X | H52: 0 | I52: 0 | J52: 0 | K52: 0 | L52: =SUM(H52:K52) -> 0
...

Sheet Task 1
A1: Cost Proposal by Task - Task 1 | C1: Enter proposed PoP as "MM/YY to MM/YY"
A2: Proposer | B2: =General!D4 -> Name
A3: Prime Proposer | B3: =General!D5 -> Name
D4: (See Note 2) | L4: (See Note 2) | T4: (See Note 2) | AB4: (See Note 2) | AJ4: (See Note 2) | AR4: (See Note 2)
D5: =Period1_Label -> FY 1 | L5: =Period2_Label -> FY 2 | T5: =Period3_Label -> FY 3 | AB5: =Period4_Label -> FY 4 | AJ5: =Period5_Label -> FY 5 | AR5: =Period6_Label -> FY 6 | AZ5: Total
A6: Direct Labor (DL) | G6: =CONCATENATE(TEXT('Proposer Constants'!C14,"MM/DD/YY")," to ",TEXT('Proposer Constants'!C15,"MM/DD/YY")) -> 06/01/25 to 05/31/26 | O6: =CONCATENATE(TEXT('Proposer Constants'!D14,"MM/DD/YY")," to ",TEXT('Proposer Constants'!D15,"MM/DD/YY")) -> 06/01/26 to 05/31/27 | W6: =CONCATENATE(TEXT('Proposer Constants'!E14,"MM/DD/YY")," to ",TEXT('Proposer Constants'!E15,"MM/DD/YY")) -> 06/01/27 to 05/31/28 | AE6: =CONCATENATE(TEXT('Proposer Constants'!F14,"MM/DD/YY")," to ",TEXT('Proposer Constants'!F15,"MM/DD/YY")) -> 06/01/28 to 05/31/29 | AM6: =CONCATENATE(TEXT('Proposer Constants'!G14,"MM/DD/YY")," to ",TEXT('Proposer Constants'!G15,"MM/DD/YY")) -> 06/01/29 to 05/31/30 | AU6: =CONCATENATE(TEXT('Proposer Constants'!H14,"MM/DD/YY")," to ",TEXT('Proposer Constants'!H15,"MM/DD/YY")) -> 06/01/30 to 05/31/31 | AZ6: (See Note 3) | BA6: X-Months
B7: Proposer's Labor Category (Note 1) | C7: Name (Last, First) | D7: Hours | E7: Hourly Labor Rate | F7: Direct Labor Cost | G7: Fringe Benefit Rate | H7: Fringe Benefit Cost | I7: Labor Overhead Rate | J7: Labor Overhead Cost | K7: Total $ | L7: Hours | M7: Hourly Labor Rate | N7: Direct Labor Cost | O7: Fringe Benefit Rate | P7: Fringe Benefit Cost | Q7: Labor Overhead Rate | R7: Labor Overhead Cost | S7: Total $ | T7: Hours | U7: Hourly Labor Rate | V7: Direct Labor Cost | W7: Fringe Benefit Rate | X7: Fringe Benefit Cost | Y7: Labor Overhead Rate | Z7: Labor Overhead Cost | AA7: Total $ | AB7: Hours | AC7: Hourly Labor Rate | AD7: Direct Labor Cost | AE7: Fringe Benefit Rate | AF7: Fringe Benefit Cost | AG7: Labor Overhead Rate | AH7: Labor Overhead Cost | AI7: Total $ | AJ7: Hours | AK7: Hourly Labor Rate | AL7: Direct Labor Cost | AM7: Fringe Benefit Rate | AN7: Fringe Benefit Cost | AO7: Labor Overhead Rate | AP7: Labor Overhead Cost | AQ7: Total $ | AR7: Hours | AS7: Hourly Labor Rate | AT7: Direct Labor Cost | AU7: Fringe Benefit Rate | AV7: Fringe Benefit Cost | AW7: Labor Overhead Rate | AX7: Labor Overhead Cost | AY7: Total $ | AZ7: Hours | BA7: Total $ | BB7: Loaded Labor Cost
A8: Milestone 1 | B8: =IF(ISBLANK('Labor Rates'!D8),"",'Labor Rates'!D8) | C8: =IF(ISBLANK('Labor Rates'!E8),"",'Labor Rates'!E8) | D8: 1920 | E8: ='Labor Rates'!#REF! -> #REF! | F8: =D8*E8 -> #REF! | G8: ='Labor Rates'!#REF! -> #REF! | H8: =F8*G8 -> #REF! | I8: ='Labor Rates'!#REF! -> #REF! | J8: =(F8+H8)*I8 -> #REF! | K8: =F8+H8+J8 -> #REF! | L8: 1920 | M8: ='Labor Rates'!#REF! -> #REF! | N8: =L8*M8 -> #REF! | O8: ='Labor Rates'!#REF! -> #REF! | P8: =N8*O8 -> #REF! | Q8: ='Labor Rates'!#REF! -> #REF! | R8: =(N8+P8)*Q8 -> #REF! | S8: =ROUND(L8*M8*(1+O8)*(1+Q8),0) -> #REF! | T8: 0 | U8: ='Labor Rates'!#REF! -> #REF! | V8: =T8*U8 -> #REF! | W8: ='Labor Rates'!#REF! -> #REF! | X8: =V8*W8 -> #REF! | Y8: ='Labor Rates'!#REF! -> #REF! | Z8: =(V8+X8)*Y8 -> #REF! | AA8: =ROUND(T8*U8*(1+W8)*(1+Y8),0) -> #REF! | AC8: ='Labor Rates'!#REF! -> #REF! | AD8: =AB8*AC8 -> #REF! | AE8: ='Labor Rates'!#REF! -> #REF! | AF8: =AD8*AE8 -> #REF! | AG8: ='Labor Rates'!#REF! -> #REF! | AH8: =(AD8+AF8)*AG8 -> #REF! | AI8: =ROUND(AB8*AC8*(1+AE8)*(1+AG8),0) -> #REF! | AK8: ='Labor Rates'!#REF! -> #REF! | AL8: =AJ8*AK8 -> #REF! | AM8: ='Labor Rates'!#REF! -> #REF! | AN8: =AL8*AM8 -> #REF! | AO8: ='Labor Rates'!#REF! -> #REF! | AP8: =(AL8+AN8)*AO8 -> #REF! | AQ8: =ROUND(AJ8*AK8*(1+AM8)*(1+AO8),0) -> #REF! | AS8: ='Labor Rates'!#REF! -> #REF! | AT8: =AR8*AS8 -> #REF! | AU8: ='Labor Rates'!#REF! -> #REF! | AV8: =AT8*AU8 -> #REF! | AW8: ='Labor Rates'!#REF! -> #REF! | AX8: =(AT8+AV8)*AW8 -> #REF! | AY8: =ROUND(AR8*AS8*(1+AU8)*(1+AW8),0) -> #REF! | AZ8: =D8+L8+T8+AB8+AJ8+AR8 -> 3840 | BA8: =F8+N8+V8+AD8+AL8+AT8 -> #REF! | BB8: =K8+S8+AA8+AI8+AQ8+AY8 -> #REF!
B9: =IF(ISBLANK('Labor Rates'!D9),"",'Labor Rates'!D9) | C9: =IF(ISBLANK('Labor Rates'!E9),"",'Labor Rates'!E9) | D9: 1920 | E9: ='Labor Rates'!#REF! -> #REF! | F9: =D9*E9 -> #REF! | G9: ='Labor Rates'!#REF! -> #REF! | H9: =F9*G9 -> #REF! | I9: ='Labor Rates'!#REF! -> #REF! | J9: =(F9+H9)*I9 -> #REF! | K9: =F9+H9+J9 -> #REF! | L9: 1920 | M9: ='Labor Rates'!#REF! -> #REF! | N9: =L9*M9 -> #REF! | O9: ='Labor Rates'!#REF! -> #REF! | P9: =N9*O9 -> #REF! | Q9: ='Labor Rates'!#REF! -> #REF! | R9: =(N9+P9)*Q9 -> #REF! | S9: =ROUND(L9*M9*(1+O9)*(1+Q9),0) -> #REF! | U9: ='Labor Rates'!#REF! -> #REF! | V9: =T9*U9 -> #REF! | W9: ='Labor Rates'!#REF! -> #REF! | X9: =V9*W9 -> #REF! | Y9: ='Labor Rates'!#REF! -> #REF! | Z9: =(V9+X9)*Y9 -> #REF! | AA9: =ROUND(T9*U9*(1+W9)*(1+Y9),0) -> #REF! | AC9: ='Labor Rates'!#REF! -> #REF! | AD9: =AB9*AC9 -> #REF! | AE9: ='Labor Rates'!#REF! -> #REF! | AF9: =AD9*AE9 -> #REF! | AG9: ='Labor Rates'!#REF! -> #REF! | AH9: =(AD9+AF9)*AG9 -> #REF! | AI9: =ROUND(AB9*AC9*(1+AE9)*(1+AG9),0) -> #REF! | AK9: ='Labor Rates'!#REF! -> #REF! | AL9: =AJ9*AK9 -> #REF! | AM9: ='Labor Rates'!#REF! -> #REF! | AN9: =AL9*AM9 -> #REF! | AO9: ='Labor Rates'!#REF! -> #REF! | AP9: =(AL9+AN9)*AO9 -> #REF! | AQ9: =ROUND(AJ9*AK9*(1+AM9)*(1+AO9),0) -> #REF! | AS9: ='Labor Rates'!#REF! -> #REF! | AT9: =AR9*AS9 -> #REF! | AU9: ='Labor Rates'!#REF! -> #REF! | AV9: =AT9*AU9 -> #REF! | AW9: ='Labor Rates'!#REF! -> #REF! | AX9: =(AT9+AV9)*AW9 -> #REF! | AY9: =ROUND(AR9*AS9*(1+AU9)*(1+AW9),0) -> #REF! | AZ9: =D9+L9+T9+AB9+AJ9+AR9 -> 3840 | BA9: =F9+N9+V9+AD9+AL9+AT9 -> #REF! | BB9: =K9+S9+AA9+AI9+AQ9+AY9 -> #REF!
